Workbook
Name GestorSecretario: Unidade!$B$20:$B$20

Sheet Unidade
A1: Identificação da Unidade
A2: Unidade | B2: ESCOLA MUNICIPAL RUY DA SILVEIRA BRITTO
A3: Código INEP/MEC | B3: 15040968
A4: Distrito | B4: DABEL
A5: Bairro | B5: Marco
A6: Rede/Vinculo | B6: Municipal
A7: Tipo de Unidade | B7: Sede
A8: Endereço da Unidade
A9: Endereço | B9: TRAVESSA DOUTOR ENEAS PINHEIRO
A10: Número | B10: 2871
A11: Complemento | B11: ENTRE PERIMETRAL E JOAO PAULO II
A12: CEP | B12: 66095-015
A13: Zona | B13: URBANA
A14: Tipo de Prédio | B14: MUNICIPAL
A15: Tipo de Contrato | B15: PROPRIA
A16: Telefone | B16: -
A17: E-mail | B17: ruydasilveirabrito@semec.belem.pa.gov.br
A18: Responsáveis da Unidade
A19: Diretor | B19: ROSEANE CONCEIÇÃO COUTO VOGADO
A20: Secretário | B20: RONALDO XAVIER DE CARVALHO

Sheet Turmas
A1: Ano | B1: Distrito | C1: Zona | D1: Bairro | E1: Tipo de Contrato | F1: Rede | G1: Código INEP | H1: Código Unidade | I1: Unidade | J1: Ensino | K1: Série | L1: Turno | M1: Turma | N1: Qt Ocupação Turma | O1: Qt Alunos Turma | P1: Qt Aluno Não Especial | Q1: Qt Aluno Especial | R1: Qt Ocupação Aluno Especial | S1: Qt Vagas Restantes | T1: Alunos | U1: Nome Geral
A2: 2026 | B2: DABEL | C2: URBANA | D2: MARCO | F2: MUNICIPAL | G2: 15040968 | H2: 36 | I2: ESCOLA MUNICIPAL RUY DA SILVEIRA BRITTO | J2: ENSINO FUNDAMENTAL | K2: CICLO IV - 1º ANO | L2: TARDE | M2: C41302 | N2: 30 | O2: 22 | P2: 22 | Q2: 0 | R2: 0 | S2: 8 | T2: Relação de Alunos | U2: =K2 & " | " & L2 & " | " & M2 & " / " & (COUNTIF(Checklist!$B$4:$B$72, "Não conforme") + COUNTIF(Checklist!$B$4:$B$72, "Não avaliado")) & " itens pendentes" -> CICLO IV - 1º ANO | TARDE | C41302 / 34 itens pendentes
A3: 2026 | B3: DABEL | C3: URBANA | D3: MARCO | F3: MUNICIPAL | G3: 15040968 | H3: 36 | I3: ESCOLA MUNICIPAL RUY DA SILVEIRA BRITTO | J3: ENSINO FUNDAMENTAL | K3: CICLO IV - 1º ANO | L3: TARDE | M3: C41301 | N3: 30 | O3: 21 | P3: 20 | Q3: 1 | R3: 1 | S3: 9 | T3: Relação de Alunos | U3: =K3 & " | " & L3 & " | " & M3 & " / " & (COUNTIF(Checklist!$B$4:$B$72, "Não conforme") + COUNTIF(Checklist!$B$4:$B$72, "Não avaliado")) & " itens pendentes" -> CICLO IV - 1º ANO | TARDE | C41301 / 34 itens pendentes
A4: 2026 | B4: DABEL | C4: URBANA | D4: MARCO | F4: MUNICIPAL | G4: 15040968 | H4: 36 | I4: ESCOLA MUNICIPAL RUY DA SILVEIRA BRITTO | J4: ENSINO FUNDAMENTAL | K4: CICLO III - 2º ANO | L4: TARDE | M4: C32302 | N4: 30 | O4: 28 | P4: 25 | Q4: 3 | R4: 3 | S4: 2 | T4: Relação de Alunos | U4: =K4 & " | " & L4 & " | " & M4 & " / " & (COUNTIF(Checklist!$B$4:$B$72, "Não conforme") + COUNTIF(Checklist!$B$4:$B$72, "Não avaliado")) & " itens pendentes" -> CICLO III - 2º ANO | TARDE | C32302 / 34 itens pendentes
A5: 2026 | B5: DABEL | C5: URBANA | D5: MARCO | F5: MUNICIPAL | G5: 15040968 | H5: 36 | I5: ESCOLA MUNICIPAL RUY DA SILVEIRA BRITTO | J5: ENSINO FUNDAMENTAL | K5: CICLO III - 2º ANO | L5: TARDE | M5: C32301 | N5: 30 | O5: 27 | P5: 24 | Q5: 3 | R5: 3 | S5: 3 | T5: Relação de Alunos | U5: =K5 & " | " & L5 & " | " & M5 & " / " & (COUNTIF(Checklist!$B$4:$B$72, "Não conforme") + COUNTIF(Checklist!$B$4:$B$72, "Não avaliado")) & " itens pendentes" -> CICLO III - 2º ANO | TARDE | C32301 / 34 itens pendentes
A6: 2026 | B6: DABEL | C6: URBANA | D6: MARCO | F6: MUNICIPAL | G6: 15040968 | H6: 36 | I6: ESCOLA MUNICIPAL RUY DA SILVEIRA BRITTO | J6: ENSINO FUNDAMENTAL | K6: CICLO III - 1º ANO | L6: TARDE | M6: C31302 | N6: 30 | O6: 26 | P6: 23 | Q6: 3 | R6: 3 | S6: 4 | T6: Relação de Alunos | U6: =K6 & " | " & L6 & " | " & M6 & " / " & (COUNTIF(Checklist!$B$4:$B$72, "Não conforme") + COUNTIF(Checklist!$B$4:$B$72, "Não avaliado")) & " itens pendentes" -> CICLO III - 1º ANO | TARDE | C31302 / 34 itens pendentes
A7: 2026 | B7: DABEL | C7: URBANA | D7: MARCO | F7: MUNICIPAL | G7: 15040968 | H7: 36 | I7: ESCOLA MUNICIPAL RUY DA SILVEIRA BRITTO | J7: ENSINO FUNDAMENTAL | K7: CICLO III - 1º ANO | L7: TARDE | M7: C31301 | N7: 30 | O7: 22 | P7: 20 | Q7: 2 | R7: 2 | S7: 8 | T7: Relação de Alunos | U7: =K7 & " | " & L7 & " | " & M7 & " / " & (COUNTIF(Checklist!$B$4:$B$72, "Não conforme") + COUNTIF(Checklist!$B$4:$B$72, "Não avaliado")) & " itens pendentes" -> CICLO III - 1º ANO | TARDE | C31301 / 34 itens pendentes
A8: 2026 | B8: DABEL | C8: URBANA | D8: MARCO | F8: MUNICIPAL | G8: 15040968 | H8: 36 | I8: ESCOLA MUNICIPAL RUY DA SILVEIRA BRITTO | J8: ENSINO FUNDAMENTAL | K8: CICLO II - 2º ANO | L8: MANHÃ | M8: C22102 | N8: 30 | O8: 28 | P8: 25 | Q8: 3 | R8: 3 | S8: 2 | T8: Relação de Alunos | U8: =K8 & " | " & L8 & " | " & M8 & " / " & (COUNTIF(Checklist!$B$4:$B$72, "Não conforme") + COUNTIF(Checklist!$B$4:$B$72, "Não avaliado")) & " itens pendentes" -> CICLO II - 2º ANO | MANHÃ | C22102 / 34 itens pendentes
A9: 2026 | B9: DABEL | C9: URBANA | D9: MARCO | F9: MUNICIPAL | G9: 15040968 | H9: 36 | I9: ESCOLA MUNICIPAL RUY DA SILVEIRA BRITTO | J9: ENSINO FUNDAMENTAL | K9: CICLO II - 2º ANO | L9: MANHÃ | M9: C22101 | N9: 30 | O9: 28 | P9: 27 | Q9: 1 | R9: 1 | S9: 2 | T9: Relação de Alunos | U9: =K9 & " | " & L9 & " | " & M9 & " / " & (COUNTIF(Checklist!$B$4:$B$72, "Não conforme") + COUNTIF(Checklist!$B$4:$B$72, "Não avaliado")) & " itens pendentes" -> CICLO II - 2º ANO | MANHÃ | C22101 / 34 itens pendentes
A10: 2026 | B10: DABEL | C10: URBANA | D10: MARCO | F10: MUNICIPAL | G10: 15040968 | H10: 36 | I10: ESCOLA MUNICIPAL RUY DA SILVEIRA BRITTO | J10: ENSINO FUNDAMENTAL | K10: CICLO II - 1º ANO | L10: MANHÃ | M10: C21102 | N10: 30 | O10: 25 | P10: 23 | Q10: 2 | R10: 2 | S10: 5 | T10: Relação de Alunos | U10: =K10 & " | " & L10 & " | " & M10 & " / " & (COUNTIF(Checklist!$B$4:$B$72, "Não conforme") + COUNTIF(Checklist!$B$4:$B$72, "Não avaliado")) & " itens pendentes" -> CICLO II - 1º ANO | MANHÃ | C21102 / 34 itens pendentes
A11: 2026 | B11: DABEL | C11: URBANA | D11: MARCO | F11: MUNICIPAL | G11: 15040968 | H11: 36 | I11: ESCOLA MUNICIPAL RUY DA SILVEIRA BRITTO | J11: ENSINO FUNDAMENTAL | K11: CICLO II - 1º ANO | L11: MANHÃ | M11: C21101 | N11: 30 | O11: 24 | P11: 21 | Q11: 3 | R11: 3 | S11: 6 | T11: Relação de Alunos | U11: =K11 & " | " & L11 & " | " & M11 & " / " & (COUNTIF(Checklist!$B$4:$B$72, "Não conforme") + COUNTIF(Checklist!$B$4:$B$72, "Não avaliado")) & " itens pendentes" -> CICLO II - 1º ANO | MANHÃ | C21101 / 34 itens pendentes
A12: 2026 | B12: DABEL | C12: URBANA | D12: MARCO | F12: MUNICIPAL | G12: 15040968 | H12: 36 | I12: ESCOLA MUNICIPAL RUY DA SILVEIRA BRITTO | J12: ENSINO FUNDAMENTAL | K12: CICLO I - 3º ANO | L12: MANHÃ | M12: C13102 | N12: 30 | O12: 24 | P12: 21 | Q12: 3 | R12: 3 | S12: 6 | T12: Relação de Alunos | U12: =K12 & " | " & L12 & " | " & M12 & " / " & (COUNTIF(Checklist!$B$4:$B$72, "Não conforme") + COUNTIF(Checklist!$B$4:$B$72, "Não avaliado")) & " itens pendentes" -> CICLO I - 3º ANO | MANHÃ | C13102 / 34 itens pendentes
A13: 2026 | B13: DABEL | C13: URBANA | D13: MARCO | F13: MUNICIPAL | G13: 15040968 | H13: 36 | I13: ESCOLA MUNICIPAL RUY DA SILVEIRA BRITTO | J13: ENSINO FUNDAMENTAL | K13: CICLO I - 3º ANO | L13: MANHÃ | M13: C13101 | N13: 30 | O13: 25 | P13: 22 | Q13: 3 | R13: 3 | S13: 5 | T13: Relação de Alunos | U13: =K13 & " | " & L13 & " | " & M13 & " / " & (COUNTIF(Checklist!$B$4:$B$72, "Não conforme") + COUNTIF(Checklist!$B$4:$B$72, "Não avaliado")) & " itens pendentes" -> CICLO I - 3º ANO | MANHÃ | C13101 / 34 itens pendentes
... A20: 2026 | B20: DABEL | C20: URBANA | D20: MARCO | F20: MUNICIPAL | G20: 15040968 | H20: 36 | I20: ESCOLA MUNICIPAL RUY DA SILVEIRA BRITTO | J20: ENSINO FUNDAMENTAL | K20: CICLO IV - 1º ANO | L20: TARDE | M20: C41303 | N20: 30 | O20: 22 | P20: 21 | Q20: 1 | R20: 1 | S20: 8 | T20: Relação de Alunos | U20: =K20 & " | " & L20 & " | " & M20 & " / " & (COUNTIF(Checklist!$B$4:$B$72, "Não conforme") + COUNTIF(Checklist!$B$4:$B$72, "Não avaliado")) & " itens pendentes" -> CICLO IV - 1º ANO | TARDE | C41303 / 34 itens pendentes

Sheet BaseDados
A1: Turma | B1: Documento | C1: Situação | D1: Responsável
A2: {=MATRIZPARACOLUNA(IF(TRANSPÔR(_xlfn._xlws.FILTER(Checklist!$A$4:$A$41, Checklist!$B$4:$B$41="Não avaliado"))<>"", Turmas!M2:M20), 3)} -> #NAME?

Sheet Checklist
A1: CICLO II - 1º ANO | MANHÃ | C21101
A2: =IF((COUNTIF(B4:B72, "Não conforme") + COUNTIF(B4:B72, "Não avaliado")) > 0, (COUNTIF(B4:B72, "Não conforme") + COUNTIF(B4:B72, "Não avaliado")) & " itens pendentes", "Checklist Conforme") -> 34 itens pendentes
A3: Checagem de Documentos Institucionais | B3: Situação | C3: Ultima Atualização | D3: Prazo | E3: Responsável | F3: Observação
A4: Ato de criação da escola | B4: Não avaliado | E4: Fulano
A5: Recibo do Censo Escolar (Autorização) | B5: Não avaliado | E5: {=GestorSecretario} -> RONALDO XAVIER DE CARVALHO
A6: Ato de autorização, credenciamento ou reconhecimento | B6: Não avaliado | E6: {=GestorSecretario} -> RONALDO XAVIER DE CARVALHO
A7: Regimento Escolar atualizado | B7: Não avaliado | E7: {=GestorSecretario} -> RONALDO XAVIER DE CARVALHO
A8: Projeto Político-Pedagógico (PPP) | B8: Não avaliado | E8: {=GestorSecretario} -> RONALDO XAVIER DE CARVALHO
A9: Calendário Escolar vigente | B9: Não avaliado | E9: {=GestorSecretario} -> RONALDO XAVIER DE CARVALHO
A10: Matriz curricular, inclusive cursos técnicos | B10: Não avaliado | E10: {=GestorSecretario} -> RONALDO XAVIER DE CARVALHO
A11: Checagem de Documentos de Secretaria Escolar | B11: Situação | C11: Ultima Atualização | D11: Prazo | E11: Gestor/Secretário | F11: Observação
A12: Livro/Pasta de Matrícula dos Alunos | B12: Não avaliado | E12: {=GestorSecretario} -> RONALDO XAVIER DE CARVALHO
A13: Livro de Atas — resultados finais, Conselho de Classe, reuniões e outros | B13: Não avaliado | E13: {=GestorSecretario} -> RONALDO XAVIER DE CARVALHO
A14: Livro de Registro de Diplomas e Certificados, quando aplicável | B14: Não avaliado | E14: {=GestorSecretario} -> RONALDO XAVIER DE CARVALHO
A15: Protocolos de entrada e saída de documentos | B15: Não avaliado | E15: {=GestorSecretario} -> RONALDO XAVIER DE CARVALHO
A16: Arquivo ativo e arquivo permanente organizados | B16: Não avaliado | E16: {=GestorSecretario} -> RONALDO XAVIER DE CARVALHO
A17: Relação nominal dos estudantes | B17: Não avaliado | E17: {=GestorSecretario} -> RONALDO XAVIER DE CARVALHO
A18: Correspondências Oficiais | B18: Não avaliado | E18: {=GestorSecretario} -> RONALDO XAVIER DE CARVALHO
A19: Inventário | B19: Não avaliado | E19: {=GestorSecretario} -> RONALDO XAVIER DE CARVALHO
A20: Checagem de Documentos dos Alunos | B20: Situação | C20: Ultima Atualização | D20: Prazo | E20: Gestor/Secretário | F20: Observação
A21: Fichas de matrícula impressas pelo SIGA e assinadas pelo responsável | B21: Não avaliado | E21: {=GestorSecretario} -> RONALDO XAVIER DE CARVALHO
A22: Histórico Escolar | B22: Não avaliado | E22: {=GestorSecretario} -> RONALDO XAVIER DE CARVALHO
A23: Pasta Individual | B23: Não avaliado | E23: {=GestorSecretario} -> RONALDO XAVIER DE CARVALHO
A24: Registro Síntese | B24: Não avaliado | E24: {=GestorSecretario} -> RONALDO XAVIER DE CARVALHO
A25: Declarações de transferência emitidas pelo SIGA | B25: Não avaliado | E25: {=GestorSecretario} -> RONALDO XAVIER DE CARVALHO
A26: Certificados e declarações emitidos | B26: Não avaliado | E26: {=GestorSecretario} -> RONALDO XAVIER DE CARVALHO
A27: Documentos pessoais do aluno e do responsável | B27: Não avaliado | E27: {=GestorSecretario} -> RONALDO XAVIER DE CARVALHO
A28: Ficha de Cancelamento/Transferência de Matrícula | B28: Não avaliado | E28: {=GestorSecretario} -> RONALDO XAVIER DE CARVALHO
A29: Controle de frequência no SIGA | B29: Não avaliado | E29: {=GestorSecretario} -> RONALDO XAVIER DE CARVALHO
A30: Checagem de Documentos dos Servidores | B30: Situação | C30: Ultima Atualização | D30: Prazo | E30: Gestor/Secretário | F30: Observação
A31: Relação atualizada dos profissionais | B31: Não avaliado | E31: {=GestorSecretario} -> RONALDO XAVIER DE CARVALHO
A32: Portarias de lotação ou designação | B32: Não avaliado | E32: {=GestorSecretario} -> RONALDO XAVIER DE CARVALHO
A33: Comprovação da habilitação dos docentes | B33: Não avaliado | E33: {=GestorSecretario} -> RONALDO XAVIER DE CARVALHO
A34: Controle de frequência dos servidores | B34: Não avaliado | E34: {=GestorSecretario} -> RONALDO XAVIER DE CARVALHO
A35: Afastamentos dos servidores — licenças e documentos médicos | B35: Não avaliado | E35: {=GestorSecretario} -> RONALDO XAVIER DE CARVALHO
A36: Checagem de Documentos dos Administrativos | B36: Situação | C36: Ultima Atualização | D36: Prazo | E36: Gestor/Secretário | F36: Observação
A37: Censo Escolar | B37: Não avaliado | E37: {=GestorSecretario} -> RONALDO XAVIER DE CARVALHO
A38: Relação nominal dos estudantes | B38: Não avaliado | E38: {=GestorSecretario} -> RONALDO XAVIER DE CARVALHO
A39: Relatórios estatísticos | B39: Não avaliado | E39: {=GestorSecretario} -> RONALDO XAVIER DE CARVALHO
A40: Correspondências oficiais | B40: Não avaliado | E40: {=GestorSecretario} -> RONALDO XAVIER DE CARVALHO
...
