Workbook

Sheet Unidade
A1: Identificação da Unidade
A2: Unidade | B2: ESCOLA MUNICIPAL RUY DA SILVEIRA BRITTO
A3: Código INEP/MEC | B3: 15040968
A4: Distrito | B4: DABEL
A5: Bairro | B5: Marco
A6: Rede/Vinculo | B6: Municipal
A7: Tipo de Unidade | B7: Sede
A8: Endereço da Unidade
A9: Endereço | B9: TRAVESSA DOUTOR ENEAS PINHEIRO
A10: Número | B10: 2871
A11: Complemento | B11: ENTRE PERIMETRAL E JOAO PAULO II
A12: CEP | B12: 66095-015
A13: Zona | B13: URBANA
A14: Tipo de Prédio | B14: MUNICIPAL
A15: Tipo de Contrato | B15: PROPRIA
A16: Telefone | B16: -
A17: E-mail | B17: ruydasilveirabrito@semec.belem.pa.gov.br
A18: Responsáveis da Unidade
A19: Diretor | B19: ROSEANE CONCEIÇÃO COUTO VOGADO
A20: Secretário | B20: RONALDO XAVIER DE CARVALHO

Sheet Turmas
A1: Ano | B1: Distrito | C1: Zona | D1: Bairro | E1: Tipo de Contrato | F1: Rede | G1: Código INEP | H1: Código Unidade | I1: Unidade | J1: Ensino | K1: Série | L1: Turno | M1: Turma | N1: Qt Ocupação Turma | O1: Qt Alunos Turma | P1: Qt Aluno Não Especial | Q1: Qt Aluno Especial | R1: Qt Ocupação Aluno Especial | S1: Qt Vagas Restantes | T1: Alunos | U1: Nome Geral
A2: 2026 | B2: DABEL | C2: URBANA | D2: MARCO | F2: MUNICIPAL | G2: 15040968 | H2: 36 | I2: ESCOLA MUNICIPAL RUY DA SILVEIRA BRITTO | J2: ENSINO FUNDAMENTAL | K2: CICLO IV - 1º ANO | L2: TARDE | M2: C41302 | N2: 30 | O2: 22 | P2: 22 | Q2: 0 | R2: 0 | S2: 8 | T2: Relação de Alunos | U2: =K2&" | "&L2&" | "&M2&" / "&(COUNTIFS(BaseDados!$B:$B,M2,BaseDados!$F:$F,"Não conforme")+COUNTIFS(BaseDados!$B:$B,M2,BaseDados!$F:$F,"Não avaliado"))&" itens pendentes" -> CICLO IV - 1º ANO | TARDE | C41302 / 34 itens pendentes
A3: 2026 | B3: DABEL | C3: URBANA | D3: MARCO | F3: MUNICIPAL | G3: 15040968 | H3: 36 | I3: ESCOLA MUNICIPAL RUY DA SILVEIRA BRITTO | J3: ENSINO FUNDAMENTAL | K3: CICLO IV - 1º ANO | L3: TARDE | M3: C41301 | N3: 30 | O3: 21 | P3: 20 | Q3: 1 | R3: 1 | S3: 9 | T3: Relação de Alunos | U3: =K3&" | "&L3&" | "&M3&" / "&(COUNTIFS(BaseDados!$B:$B,M3,BaseDados!$F:$F,"Não conforme")+COUNTIFS(BaseDados!$B:$B,M3,BaseDados!$F:$F,"Não avaliado"))&" itens pendentes" -> CICLO IV - 1º ANO | TARDE | C41301 / 34 itens pendentes
A4: 2026 | B4: DABEL | C4: URBANA | D4: MARCO | F4: MUNICIPAL | G4: 15040968 | H4: 36 | I4: ESCOLA MUNICIPAL RUY DA SILVEIRA BRITTO | J4: ENSINO FUNDAMENTAL | K4: CICLO III - 2º ANO | L4: TARDE | M4: C32302 | N4: 30 | O4: 28 | P4: 25 | Q4: 3 | R4: 3 | S4: 2 | T4: Relação de Alunos | U4: =K4&" | "&L4&" | "&M4&" / "&(COUNTIFS(BaseDados!$B:$B,M4,BaseDados!$F:$F,"Não conforme")+COUNTIFS(BaseDados!$B:$B,M4,BaseDados!$F:$F,"Não avaliado"))&" itens pendentes" -> CICLO III - 2º ANO | TARDE | C32302 / 34 itens pendentes
A5: 2026 | B5: DABEL | C5: URBANA | D5: MARCO | F5: MUNICIPAL | G5: 15040968 | H5: 36 | I5: ESCOLA MUNICIPAL RUY DA SILVEIRA BRITTO | J5: ENSINO FUNDAMENTAL | K5: CICLO III - 2º ANO | L5: TARDE | M5: C32301 | N5: 30 | O5: 27 | P5: 24 | Q5: 3 | R5: 3 | S5: 3 | T5: Relação de Alunos | U5: =K5&" | "&L5&" | "&M5&" / "&(COUNTIFS(BaseDados!$B:$B,M5,BaseDados!$F:$F,"Não conforme")+COUNTIFS(BaseDados!$B:$B,M5,BaseDados!$F:$F,"Não avaliado"))&" itens pendentes" -> CICLO III - 2º ANO | TARDE | C32301 / 34 itens pendentes
A6: 2026 | B6: DABEL | C6: URBANA | D6: MARCO | F6: MUNICIPAL | G6: 15040968 | H6: 36 | I6: ESCOLA MUNICIPAL RUY DA SILVEIRA BRITTO | J6: ENSINO FUNDAMENTAL | K6: CICLO III - 1º ANO | L6: TARDE | M6: C31302 | N6: 30 | O6: 26 | P6: 23 | Q6: 3 | R6: 3 | S6: 4 | T6: Relação de Alunos | U6: =K6&" | "&L6&" | "&M6&" / "&(COUNTIFS(BaseDados!$B:$B,M6,BaseDados!$F:$F,"Não conforme")+COUNTIFS(BaseDados!$B:$B,M6,BaseDados!$F:$F,"Não avaliado"))&" itens pendentes" -> CICLO III - 1º ANO | TARDE | C31302 / 34 itens pendentes
A7: 2026 | B7: DABEL | C7: URBANA | D7: MARCO | F7: MUNICIPAL | G7: 15040968 | H7: 36 | I7: ESCOLA MUNICIPAL RUY DA SILVEIRA BRITTO | J7: ENSINO FUNDAMENTAL | K7: CICLO III - 1º ANO | L7: TARDE | M7: C31301 | N7: 30 | O7: 22 | P7: 20 | Q7: 2 | R7: 2 | S7: 8 | T7: Relação de Alunos | U7: =K7&" | "&L7&" | "&M7&" / "&(COUNTIFS(BaseDados!$B:$B,M7,BaseDados!$F:$F,"Não conforme")+COUNTIFS(BaseDados!$B:$B,M7,BaseDados!$F:$F,"Não avaliado"))&" itens pendentes" -> CICLO III - 1º ANO | TARDE | C31301 / 34 itens pendentes
A8: 2026 | B8: DABEL | C8: URBANA | D8: MARCO | F8: MUNICIPAL | G8: 15040968 | H8: 36 | I8: ESCOLA MUNICIPAL RUY DA SILVEIRA BRITTO | J8: ENSINO FUNDAMENTAL | K8: CICLO II - 2º ANO | L8: MANHÃ | M8: C22102 | N8: 30 | O8: 28 | P8: 25 | Q8: 3 | R8: 3 | S8: 2 | T8: Relação de Alunos | U8: =K8&" | "&L8&" | "&M8&" / "&(COUNTIFS(BaseDados!$B:$B,M8,BaseDados!$F:$F,"Não conforme")+COUNTIFS(BaseDados!$B:$B,M8,BaseDados!$F:$F,"Não avaliado"))&" itens pendentes" -> CICLO II - 2º ANO | MANHÃ | C22102 / 34 itens pendentes
A9: 2026 | B9: DABEL | C9: URBANA | D9: MARCO | F9: MUNICIPAL | G9: 15040968 | H9: 36 | I9: ESCOLA MUNICIPAL RUY DA SILVEIRA BRITTO | J9: ENSINO FUNDAMENTAL | K9: CICLO II - 2º ANO | L9: MANHÃ | M9: C22101 | N9: 30 | O9: 28 | P9: 27 | Q9: 1 | R9: 1 | S9: 2 | T9: Relação de Alunos | U9: =K9&" | "&L9&" | "&M9&" / "&(COUNTIFS(BaseDados!$B:$B,M9,BaseDados!$F:$F,"Não conforme")+COUNTIFS(BaseDados!$B:$B,M9,BaseDados!$F:$F,"Não avaliado"))&" itens pendentes" -> CICLO II - 2º ANO | MANHÃ | C22101 / 34 itens pendentes
A10: 2026 | B10: DABEL | C10: URBANA | D10: MARCO | F10: MUNICIPAL | G10: 15040968 | H10: 36 | I10: ESCOLA MUNICIPAL RUY DA SILVEIRA BRITTO | J10: ENSINO FUNDAMENTAL | K10: CICLO II - 1º ANO | L10: MANHÃ | M10: C21102 | N10: 30 | O10: 25 | P10: 23 | Q10: 2 | R10: 2 | S10: 5 | T10: Relação de Alunos | U10: =K10&" | "&L10&" | "&M10&" / "&(COUNTIFS(BaseDados!$B:$B,M10,BaseDados!$F:$F,"Não conforme")+COUNTIFS(BaseDados!$B:$B,M10,BaseDados!$F:$F,"Não avaliado"))&" itens pendentes" -> CICLO II - 1º ANO | MANHÃ | C21102 / 34 itens pendentes
A11: 2026 | B11: DABEL | C11: URBANA | D11: MARCO | F11: MUNICIPAL | G11: 15040968 | H11: 36 | I11: ESCOLA MUNICIPAL RUY DA SILVEIRA BRITTO | J11: ENSINO FUNDAMENTAL | K11: CICLO II - 1º ANO | L11: MANHÃ | M11: C21101 | N11: 30 | O11: 24 | P11: 21 | Q11: 3 | R11: 3 | S11: 6 | T11: Relação de Alunos | U11: =K11&" | "&L11&" | "&M11&" / "&(COUNTIFS(BaseDados!$B:$B,M11,BaseDados!$F:$F,"Não conforme")+COUNTIFS(BaseDados!$B:$B,M11,BaseDados!$F:$F,"Não avaliado"))&" itens pendentes" -> CICLO II - 1º ANO | MANHÃ | C21101 / 34 itens pendentes
A12: 2026 | B12: DABEL | C12: URBANA | D12: MARCO | F12: MUNICIPAL | G12: 15040968 | H12: 36 | I12: ESCOLA MUNICIPAL RUY DA SILVEIRA BRITTO | J12: ENSINO FUNDAMENTAL | K12: CICLO I - 3º ANO | L12: MANHÃ | M12: C13102 | N12: 30 | O12: 24 | P12: 21 | Q12: 3 | R12: 3 | S12: 6 | T12: Relação de Alunos | U12: =K12&" | "&L12&" | "&M12&" / "&(COUNTIFS(BaseDados!$B:$B,M12,BaseDados!$F:$F,"Não conforme")+COUNTIFS(BaseDados!$B:$B,M12,BaseDados!$F:$F,"Não avaliado"))&" itens pendentes" -> CICLO I - 3º ANO | MANHÃ | C13102 / 34 itens pendentes
A13: 2026 | B13: DABEL | C13: URBANA | D13: MARCO | F13: MUNICIPAL | G13: 15040968 | H13: 36 | I13: ESCOLA MUNICIPAL RUY DA SILVEIRA BRITTO | J13: ENSINO FUNDAMENTAL | K13: CICLO I - 3º ANO | L13: MANHÃ | M13: C13101 | N13: 30 | O13: 25 | P13: 22 | Q13: 3 | R13: 3 | S13: 5 | T13: Relação de Alunos | U13: =K13&" | "&L13&" | "&M13&" / "&(COUNTIFS(BaseDados!$B:$B,M13,BaseDados!$F:$F,"Não conforme")+COUNTIFS(BaseDados!$B:$B,M13,BaseDados!$F:$F,"Não avaliado"))&" itens pendentes" -> CICLO I - 3º ANO | MANHÃ | C13101 / 34 itens pendentes
... A20: 2026 | B20: DABEL | C20: URBANA | D20: MARCO | F20: MUNICIPAL | G20: 15040968 | H20: 36 | I20: ESCOLA MUNICIPAL RUY DA SILVEIRA BRITTO | J20: ENSINO FUNDAMENTAL | K20: CICLO IV - 1º ANO | L20: TARDE | M20: C41303 | N20: 30 | O20: 22 | P20: 21 | Q20: 1 | R20: 1 | S20: 8 | T20: Relação de Alunos | U20: =K20&" | "&L20&" | "&M20&" / "&(COUNTIFS(BaseDados!$B:$B,M20,BaseDados!$F:$F,"Não conforme")+COUNTIFS(BaseDados!$B:$B,M20,BaseDados!$F:$F,"Não avaliado"))&" itens pendentes" -> CICLO IV - 1º ANO | TARDE | C41303 / 34 itens pendentes

Sheet BaseDados
A1: Chave | B1: Turma | C1: Nº Item | D1: Seção | E1: Documento | F1: Situação | G1: Última Atualização | H1: Prazo | I1: Observação | J1: Série | Turno
A2: =B2&"|"&C2 -> C41302|1 | B2: C41302 | C2: 1 | D2: Documentos Institucionais | E2: Ato de criação da escola | F2: Não avaliado | J2: =INDEX(Turmas!$K:$K,MATCH(B2,Turmas!$M:$M,0))&" | "&INDEX(Turmas!$L:$L,MATCH(B2,Turmas!$M:$M,0)) -> CICLO IV - 1º ANO | TARDE
A3: =B3&"|"&C3 -> C41302|2 | B3: C41302 | C3: 2 | D3: Documentos Institucionais | E3: Recibo do Censo Escolar (Autorização) | F3: Não avaliado | J3: =INDEX(Turmas!$K:$K,MATCH(B3,Turmas!$M:$M,0))&" | "&INDEX(Turmas!$L:$L,MATCH(B3,Turmas!$M:$M,0)) -> CICLO IV - 1º ANO | TARDE
A4: =B4&"|"&C4 -> C41302|3 | B4: C41302 | C4: 3 | D4: Documentos Institucionais | E4: Ato de autorização, credenciamento ou reconhecimento | F4: Não avaliado | J4: =INDEX(Turmas!$K:$K,MATCH(B4,Turmas!$M:$M,0))&" | "&INDEX(Turmas!$L:$L,MATCH(B4,Turmas!$M:$M,0)) -> CICLO IV - 1º ANO | TARDE
A5: =B5&"|"&C5 -> C41302|4 | B5: C41302 | C5: 4 | D5: Documentos Institucionais | E5: Regimento Escolar atualizado | F5: Não avaliado | J5: =INDEX(Turmas!$K:$K,MATCH(B5,Turmas!$M:$M,0))&" | "&INDEX(Turmas!$L:$L,MATCH(B5,Turmas!$M:$M,0)) -> CICLO IV - 1º ANO | TARDE
A6: =B6&"|"&C6 -> C41302|5 | B6: C41302 | C6: 5 | D6: Documentos Institucionais | E6: Projeto Político-Pedagógico (PPP) | F6: Não avaliado | J6: =INDEX(Turmas!$K:$K,MATCH(B6,Turmas!$M:$M,0))&" | "&INDEX(Turmas!$L:$L,MATCH(B6,Turmas!$M:$M,0)) -> CICLO IV - 1º ANO | TARDE
A7: =B7&"|"&C7 -> C41302|6 | B7: C41302 | C7: 6 | D7: Documentos Institucionais | E7: Calendário Escolar vigente | F7: Não avaliado | J7: =INDEX(Turmas!$K:$K,MATCH(B7,Turmas!$M:$M,0))&" | "&INDEX(Turmas!$L:$L,MATCH(B7,Turmas!$M:$M,0)) -> CICLO IV - 1º ANO | TARDE
A8: =B8&"|"&C8 -> C41302|7 | B8: C41302 | C8: 7 | D8: Documentos Institucionais | E8: Matriz curricular, inclusive cursos técnicos | F8: Não avaliado | J8: =INDEX(Turmas!$K:$K,MATCH(B8,Turmas!$M:$M,0))&" | "&INDEX(Turmas!$L:$L,MATCH(B8,Turmas!$M:$M,0)) -> CICLO IV - 1º ANO | TARDE
A9: =B9&"|"&C9 -> C41302|8 | B9: C41302 | C9: 8 | D9: Documentos de Secretaria Escolar | E9: Livro/Pasta de Matrícula dos Alunos | F9: Não avaliado | J9: =INDEX(Turmas!$K:$K,MATCH(B9,Turmas!$M:$M,0))&" | "&INDEX(Turmas!$L:$L,MATCH(B9,Turmas!$M:$M,0)) -> CICLO IV - 1º ANO | TARDE
A10: =B10&"|"&C10 -> C41302|9 | B10: C41302 | C10: 9 | D10: Documentos de Secretaria Escolar | E10: Livro de Atas — resultados finais, Conselho de Classe, reuniões e outros | F10: Não avaliado | J10: =INDEX(Turmas!$K:$K,MATCH(B10,Turmas!$M:$M,0))&" | "&INDEX(Turmas!$L:$L,MATCH(B10,Turmas!$M:$M,0)) -> CICLO IV - 1º ANO | TARDE
A11: =B11&"|"&C11 -> C41302|10 | B11: C41302 | C11: 10 | D11: Documentos de Secretaria Escolar | E11: Livro de Registro de Diplomas e Certificados, quando aplicável | F11: Não avaliado | J11: =INDEX(Turmas!$K:$K,MATCH(B11,Turmas!$M:$M,0))&" | "&INDEX(Turmas!$L:$L,MATCH(B11,Turmas!$M:$M,0)) -> CICLO IV - 1º ANO | TARDE
A12: =B12&"|"&C12 -> C41302|11 | B12: C41302 | C12: 11 | D12: Documentos de Secretaria Escolar | E12: Protocolos de entrada e saída de documentos | F12: Não avaliado | J12: =INDEX(Turmas!$K:$K,MATCH(B12,Turmas!$M:$M,0))&" | "&INDEX(Turmas!$L:$L,MATCH(B12,Turmas!$M:$M,0)) -> CICLO IV - 1º ANO | TARDE
A13: =B13&"|"&C13 -> C41302|12 | B13: C41302 | C13: 12 | D13: Documentos de Secretaria Escolar | E13: Arquivo ativo e arquivo permanente organizados | F13: Não avaliado | J13: =INDEX(Turmas!$K:$K,MATCH(B13,Turmas!$M:$M,0))&" | "&INDEX(Turmas!$L:$L,MATCH(B13,Turmas!$M:$M,0)) -> CICLO IV - 1º ANO | TARDE
... A647: =B647&"|"&C647 -> C41303|34 | B647: C41303 | C647: 34 | D647: Documentos dos Administrativos | E647: Livros de protocolo | F647: Não avaliado | J647: =INDEX(Turmas!$K:$K,MATCH(B647,Turmas!$M:$M,0))&" | "&INDEX(Turmas!$L:$L,MATCH(B647,Turmas!$M:$M,0)) -> CICLO IV - 1º ANO | TARDE

Sheet Checklist
A1: CICLO II - 1º ANO | MANHÃ | C21101 | G1: =IFERROR(INDEX(Turmas!$M:$M,SUMPRODUCT(ISNUMBER(SEARCH(Turmas!$M$2:$M$20,$A$1))*ROW(Turmas!$M$2:$M$20))),"") -> C21101
A2: =IF((COUNTIF(B4:B72, "Não conforme") + COUNTIF(B4:B72, "Não avaliado")) > 0, (COUNTIF(B4:B72, "Não conforme") + COUNTIF(B4:B72, "Não avaliado")) & " itens pendentes", "Checklist Conforme") -> 34 itens pendentes | G2: Código da turma selecionada (auxiliar)
A3: Checagem de Documentos Institucionais | B3: Situação | C3: Ultima Atualização | D3: Prazo | E3: Responsável | F3: Observação
A4: Ato de criação da escola | B4: =IFERROR(IF(INDEX(BaseDados!$F:$F,MATCH($G$1&"|"&$G4,BaseDados!$A:$A,0))="","",INDEX(BaseDados!$F:$F,MATCH($G$1&"|"&$G4,BaseDados!$A:$A,0))),"") -> Não avaliado | C4: =IFERROR(IF(INDEX(BaseDados!$G:$G,MATCH($G$1&"|"&$G4,BaseDados!$A:$A,0))="","",INDEX(BaseDados!$G:$G,MATCH($G$1&"|"&$G4,BaseDados!$A:$A,0))),"") | D4: =IFERROR(IF(INDEX(BaseDados!$H:$H,MATCH($G$1&"|"&$G4,BaseDados!$A:$A,0))="","",INDEX(BaseDados!$H:$H,MATCH($G$1&"|"&$G4,BaseDados!$A:$A,0))),"") | E4: Fulano | F4: =IFERROR(IF(INDEX(BaseDados!$I:$I,MATCH($G$1&"|"&$G4,BaseDados!$A:$A,0))="","",INDEX(BaseDados!$I:$I,MATCH($G$1&"|"&$G4,BaseDados!$A:$A,0))),"") | G4: 1
A5: Recibo do Censo Escolar (Autorização) | B5: =IFERROR(IF(INDEX(BaseDados!$F:$F,MATCH($G$1&"|"&$G5,BaseDados!$A:$A,0))="","",INDEX(BaseDados!$F:$F,MATCH($G$1&"|"&$G5,BaseDados!$A:$A,0))),"") -> Não avaliado | C5: =IFERROR(IF(INDEX(BaseDados!$G:$G,MATCH($G$1&"|"&$G5,BaseDados!$A:$A,0))="","",INDEX(BaseDados!$G:$G,MATCH($G$1&"|"&$G5,BaseDados!$A:$A,0))),"") | D5: =IFERROR(IF(INDEX(BaseDados!$H:$H,MATCH($G$1&"|"&$G5,BaseDados!$A:$A,0))="","",INDEX(BaseDados!$H:$H,MATCH($G$1&"|"&$G5,BaseDados!$A:$A,0))),"") | E5: {=GestorSecretario} -> RONALDO XAVIER DE CARVALHO | F5: =IFERROR(IF(INDEX(BaseDados!$I:$I,MATCH($G$1&"|"&$G5,BaseDados!$A:$A,0))="","",INDEX(BaseDados!$I:$I,MATCH($G$1&"|"&$G5,BaseDados!$A:$A,0))),"") | G5: 2
A6: Ato de autorização, credenciamento ou reconhecimento | B6: =IFERROR(IF(INDEX(BaseDados!$F:$F,MATCH($G$1&"|"&$G6,BaseDados!$A:$A,0))="","",INDEX(BaseDados!$F:$F,MATCH($G$1&"|"&$G6,BaseDados!$A:$A,0))),"") -> Não avaliado | C6: =IFERROR(IF(INDEX(BaseDados!$G:$G,MATCH($G$1&"|"&$G6,BaseDados!$A:$A,0))="","",INDEX(BaseDados!$G:$G,MATCH($G$1&"|"&$G6,BaseDados!$A:$A,0))),"") | D6: =IFERROR(IF(INDEX(BaseDados!$H:$H,MATCH($G$1&"|"&$G6,BaseDados!$A:$A,0))="","",INDEX(BaseDados!$H:$H,MATCH($G$1&"|"&$G6,BaseDados!$A:$A,0))),"") | E6: {=GestorSecretario} -> RONALDO XAVIER DE CARVALHO | F6: =IFERROR(IF(INDEX(BaseDados!$I:$I,MATCH($G$1&"|"&$G6,BaseDados!$A:$A,0))="","",INDEX(BaseDados!$I:$I,MATCH($G$1&"|"&$G6,BaseDados!$A:$A,0))),"") | G6: 3
A7: Regimento Escolar atualizado | B7: =IFERROR(IF(INDEX(BaseDados!$F:$F,MATCH($G$1&"|"&$G7,BaseDados!$A:$A,0))="","",INDEX(BaseDados!$F:$F,MATCH($G$1&"|"&$G7,BaseDados!$A:$A,0))),"") -> Não avaliado | C7: =IFERROR(IF(INDEX(BaseDados!$G:$G,MATCH($G$1&"|"&$G7,BaseDados!$A:$A,0))="","",INDEX(BaseDados!$G:$G,MATCH($G$1&"|"&$G7,BaseDados!$A:$A,0))),"") | D7: =IFERROR(IF(INDEX(BaseDados!$H:$H,MATCH($G$1&"|"&$G7,BaseDados!$A:$A,0))="","",INDEX(BaseDados!$H:$H,MATCH($G$1&"|"&$G7,BaseDados!$A:$A,0))),"") | E7: {=GestorSecretario} -> RONALDO XAVIER DE CARVALHO | F7: =IFERROR(IF(INDEX(BaseDados!$I:$I,MATCH($G$1&"|"&$G7,BaseDados!$A:$A,0))="","",INDEX(BaseDados!$I:$I,MATCH($G$1&"|"&$G7,BaseDados!$A:$A,0))),"") | G7: 4
A8: Projeto Político-Pedagógico (PPP) | B8: =IFERROR(IF(INDEX(BaseDados!$F:$F,MATCH($G$1&"|"&$G8,BaseDados!$A:$A,0))="","",INDEX(BaseDados!$F:$F,MATCH($G$1&"|"&$G8,BaseDados!$A:$A,0))),"") -> Não avaliado | C8: =IFERROR(IF(INDEX(BaseDados!$G:$G,MATCH($G$1&"|"&$G8,BaseDados!$A:$A,0))="","",INDEX(BaseDados!$G:$G,MATCH($G$1&"|"&$G8,BaseDados!$A:$A,0))),"") | D8: =IFERROR(IF(INDEX(BaseDados!$H:$H,MATCH($G$1&"|"&$G8,BaseDados!$A:$A,0))="","",INDEX(BaseDados!$H:$H,MATCH($G$1&"|"&$G8,BaseDados!$A:$A,0))),"") | E8: {=GestorSecretario} -> RONALDO XAVIER DE CARVALHO | F8: =IFERROR(IF(INDEX(BaseDados!$I:$I,MATCH($G$1&"|"&$G8,BaseDados!$A:$A,0))="","",INDEX(BaseDados!$I:$I,MATCH($G$1&"|"&$G8,BaseDados!$A:$A,0))),"") | G8: 5
A9: Calendário Escolar vigente | B9: =IFERROR(IF(INDEX(BaseDados!$F:$F,MATCH($G$1&"|"&$G9,BaseDados!$A:$A,0))="","",INDEX(BaseDados!$F:$F,MATCH($G$1&"|"&$G9,BaseDados!$A:$A,0))),"") -> Não avaliado | C9: =IFERROR(IF(INDEX(BaseDados!$G:$G,MATCH($G$1&"|"&$G9,BaseDados!$A:$A,0))="","",INDEX(BaseDados!$G:$G,MATCH($G$1&"|"&$G9,BaseDados!$A:$A,0))),"") | D9: =IFERROR(IF(INDEX(BaseDados!$H:$H,MATCH($G$1&"|"&$G9,BaseDados!$A:$A,0))="","",INDEX(BaseDados!$H:$H,MATCH($G$1&"|"&$G9,BaseDados!$A:$A,0))),"") | E9: {=GestorSecretario} -> RONALDO XAVIER DE CARVALHO | F9: =IFERROR(IF(INDEX(BaseDados!$I:$I,MATCH($G$1&"|"&$G9,BaseDados!$A:$A,0))="","",INDEX(BaseDados!$I:$I,MATCH($G$1&"|"&$G9,BaseDados!$A:$A,0))),"") | G9: 6
A10: Matriz curricular, inclusive cursos técnicos | B10: =IFERROR(IF(INDEX(BaseDados!$F:$F,MATCH($G$1&"|"&$G10,BaseDados!$A:$A,0))="","",INDEX(BaseDados!$F:$F,MATCH($G$1&"|"&$G10,BaseDados!$A:$A,0))),"") -> Não avaliado | C10: =IFERROR(IF(INDEX(BaseDados!$G:$G,MATCH($G$1&"|"&$G10,BaseDados!$A:$A,0))="","",INDEX(BaseDados!$G:$G,MATCH($G$1&"|"&$G10,BaseDados!$A:$A,0))),"") | D10: =IFERROR(IF(INDEX(BaseDados!$H:$H,MATCH($G$1&"|"&$G10,BaseDados!$A:$A,0))="","",INDEX(BaseDados!$H:$H,MATCH($G$1&"|"&$G10,BaseDados!$A:$A,0))),"") | E10: {=GestorSecretario} -> RONALDO XAVIER DE CARVALHO | F10: =IFERROR(IF(INDEX(BaseDados!$I:$I,MATCH($G$1&"|"&$G10,BaseDados!$A:$A,0))="","",INDEX(BaseDados!$I:$I,MATCH($G$1&"|"&$G10,BaseDados!$A:$A,0))),"") | G10: 7
A11: Checagem de Documentos de Secretaria Escolar | B11: Situação | C11: Ultima Atualização | D11: Prazo | E11: Gestor/Secretário | F11: Observação
A12: Livro/Pasta de Matrícula dos Alunos | B12: =IFERROR(IF(INDEX(BaseDados!$F:$F,MATCH($G$1&"|"&$G12,BaseDados!$A:$A,0))="","",INDEX(BaseDados!$F:$F,MATCH($G$1&"|"&$G12,BaseDados!$A:$A,0))),"") -> Não avaliado | C12: =IFERROR(IF(INDEX(BaseDados!$G:$G,MATCH($G$1&"|"&$G12,BaseDados!$A:$A,0))="","",INDEX(BaseDados!$G:$G,MATCH($G$1&"|"&$G12,BaseDados!$A:$A,0))),"") | D12: =IFERROR(IF(INDEX(BaseDados!$H:$H,MATCH($G$1&"|"&$G12,BaseDados!$A:$A,0))="","",INDEX(BaseDados!$H:$H,MATCH($G$1&"|"&$G12,BaseDados!$A:$A,0))),"") | E12: {=GestorSecretario} -> RONALDO XAVIER DE CARVALHO | F12: =IFERROR(IF(INDEX(BaseDados!$I:$I,MATCH($G$1&"|"&$G12,BaseDados!$A:$A,0))="","",INDEX(BaseDados!$I:$I,MATCH($G$1&"|"&$G12,BaseDados!$A:$A,0))),"") | G12: 8
A13: Livro de Atas — resultados finais, Conselho de Classe, reuniões e outros | B13: =IFERROR(IF(INDEX(BaseDados!$F:$F,MATCH($G$1&"|"&$G13,BaseDados!$A:$A,0))="","",INDEX(BaseDados!$F:$F,MATCH($G$1&"|"&$G13,BaseDados!$A:$A,0))),"") -> Não avaliado | C13: =IFERROR(IF(INDEX(BaseDados!$G:$G,MATCH($G$1&"|"&$G13,BaseDados!$A:$A,0))="","",INDEX(BaseDados!$G:$G,MATCH($G$1&"|"&$G13,BaseDados!$A:$A,0))),"") | D13: =IFERROR(IF(INDEX(BaseDados!$H:$H,MATCH($G$1&"|"&$G13,BaseDados!$A:$A,0))="","",INDEX(BaseDados!$H:$H,MATCH($G$1&"|"&$G13,BaseDados!$A:$A,0))),"") | E13: {=GestorSecretario} -> RONALDO XAVIER DE CARVALHO | F13: =IFERROR(IF(INDEX(BaseDados!$I:$I,MATCH($G$1&"|"&$G13,BaseDados!$A:$A,0))="","",INDEX(BaseDados!$I:$I,MATCH($G$1&"|"&$G13,BaseDados!$A:$A,0))),"") | G13: 9
A14: Livro de Registro de Diplomas e Certificados, quando aplicável | B14: =IFERROR(IF(INDEX(BaseDados!$F:$F,MATCH($G$1&"|"&$G14,BaseDados!$A:$A,0))="","",INDEX(BaseDados!$F:$F,MATCH($G$1&"|"&$G14,BaseDados!$A:$A,0))),"") -> Não avaliado | C14: =IFERROR(IF(INDEX(BaseDados!$G:$G,MATCH($G$1&"|"&$G14,BaseDados!$A:$A,0))="","",INDEX(BaseDados!$G:$G,MATCH($G$1&"|"&$G14,BaseDados!$A:$A,0))),"") | D14: =IFERROR(IF(INDEX(BaseDados!$H:$H,MATCH($G$1&"|"&$G14,BaseDados!$A:$A,0))="","",INDEX(BaseDados!$H:$H,MATCH($G$1&"|"&$G14,BaseDados!$A:$A,0))),"") | E14: {=GestorSecretario} -> RONALDO XAVIER DE CARVALHO | F14: =IFERROR(IF(INDEX(BaseDados!$I:$I,MATCH($G$1&"|"&$G14,BaseDados!$A:$A,0))="","",INDEX(BaseDados!$I:$I,MATCH($G$1&"|"&$G14,BaseDados!$A:$A,0))),"") | G14: 10
A15: Protocolos de entrada e saída de documentos | B15: =IFERROR(IF(INDEX(BaseDados!$F:$F,MATCH($G$1&"|"&$G15,BaseDados!$A:$A,0))="","",INDEX(BaseDados!$F:$F,MATCH($G$1&"|"&$G15,BaseDados!$A:$A,0))),"") -> Não avaliado | C15: =IFERROR(IF(INDEX(BaseDados!$G:$G,MATCH($G$1&"|"&$G15,BaseDados!$A:$A,0))="","",INDEX(BaseDados!$G:$G,MATCH($G$1&"|"&$G15,BaseDados!$A:$A,0))),"") | D15: =IFERROR(IF(INDEX(BaseDados!$H:$H,MATCH($G$1&"|"&$G15,BaseDados!$A:$A,0))="","",INDEX(BaseDados!$H:$H,MATCH($G$1&"|"&$G15,BaseDados!$A:$A,0))),"") | E15: {=GestorSecretario} -> RONALDO XAVIER DE CARVALHO | F15: =IFERROR(IF(INDEX(BaseDados!$I:$I,MATCH($G$1&"|"&$G15,BaseDados!$A:$A,0))="","",INDEX(BaseDados!$I:$I,MATCH($G$1&"|"&$G15,BaseDados!$A:$A,0))),"") | G15: 11
A16: Arquivo ativo e arquivo permanente organizados | B16: =IFERROR(IF(INDEX(BaseDados!$F:$F,MATCH($G$1&"|"&$G16,BaseDados!$A:$A,0))="","",INDEX(BaseDados!$F:$F,MATCH($G$1&"|"&$G16,BaseDados!$A:$A,0))),"") -> Não avaliado | C16: =IFERROR(IF(INDEX(BaseDados!$G:$G,MATCH($G$1&"|"&$G16,BaseDados!$A:$A,0))="","",INDEX(BaseDados!$G:$G,MATCH($G$1&"|"&$G16,BaseDados!$A:$A,0))),"") | D16: =IFERROR(IF(INDEX(BaseDados!$H:$H,MATCH($G$1&"|"&$G16,BaseDados!$A:$A,0))="","",INDEX(BaseDados!$H:$H,MATCH($G$1&"|"&$G16,BaseDados!$A:$A,0))),"") | E16: {=GestorSecretario} -> RONALDO XAVIER DE CARVALHO | F16: =IFERROR(IF(INDEX(BaseDados!$I:$I,MATCH($G$1&"|"&$G16,BaseDados!$A:$A,0))="","",INDEX(BaseDados!$I:$I,MATCH($G$1&"|"&$G16,BaseDados!$A:$A,0))),"") | G16: 12
A17: Relação nominal dos estudantes | B17: =IFERROR(IF(INDEX(BaseDados!$F:$F,MATCH($G$1&"|"&$G17,BaseDados!$A:$A,0))="","",INDEX(BaseDados!$F:$F,MATCH($G$1&"|"&$G17,BaseDados!$A:$A,0))),"") -> Não avaliado | C17: =IFERROR(IF(INDEX(BaseDados!$G:$G,MATCH($G$1&"|"&$G17,BaseDados!$A:$A,0))="","",INDEX(BaseDados!$G:$G,MATCH($G$1&"|"&$G17,BaseDados!$A:$A,0))),"") | D17: =IFERROR(IF(INDEX(BaseDados!$H:$H,MATCH($G$1&"|"&$G17,BaseDados!$A:$A,0))="","",INDEX(BaseDados!$H:$H,MATCH($G$1&"|"&$G17,BaseDados!$A:$A,0))),"") | E17: {=GestorSecretario} -> RONALDO XAVIER DE CARVALHO | F17: =IFERROR(IF(INDEX(BaseDados!$I:$I,MATCH($G$1&"|"&$G17,BaseDados!$A:$A,0))="","",INDEX(BaseDados!$I:$I,MATCH($G$1&"|"&$G17,BaseDados!$A:$A,0))),"") | G17: 13
A18: Correspondências Oficiais | B18: =IFERROR(IF(INDEX(BaseDados!$F:$F,MATCH($G$1&"|"&$G18,BaseDados!$A:$A,0))="","",INDEX(BaseDados!$F:$F,MATCH($G$1&"|"&$G18,BaseDados!$A:$A,0))),"") -> Não avaliado | C18: =IFERROR(IF(INDEX(BaseDados!$G:$G,MATCH($G$1&"|"&$G18,BaseDados!$A:$A,0))="","",INDEX(BaseDados!$G:$G,MATCH($G$1&"|"&$G18,BaseDados!$A:$A,0))),"") | D18: =IFERROR(IF(INDEX(BaseDados!$H:$H,MATCH($G$1&"|"&$G18,BaseDados!$A:$A,0))="","",INDEX(BaseDados!$H:$H,MATCH($G$1&"|"&$G18,BaseDados!$A:$A,0))),"") | E18: {=GestorSecretario} -> RONALDO XAVIER DE CARVALHO | F18: =IFERROR(IF(INDEX(BaseDados!$I:$I,MATCH($G$1&"|"&$G18,BaseDados!$A:$A,0))="","",INDEX(BaseDados!$I:$I,MATCH($G$1&"|"&$G18,BaseDados!$A:$A,0))),"") | G18: 14
A19: Inventário | B19: =IFERROR(IF(INDEX(BaseDados!$F:$F,MATCH($G$1&"|"&$G19,BaseDados!$A:$A,0))="","",INDEX(BaseDados!$F:$F,MATCH($G$1&"|"&$G19,BaseDados!$A:$A,0))),"") -> Não avaliado | C19: =IFERROR(IF(INDEX(BaseDados!$G:$G,MATCH($G$1&"|"&$G19,BaseDados!$A:$A,0))="","",INDEX(BaseDados!$G:$G,MATCH($G$1&"|"&$G19,BaseDados!$A:$A,0))),"") | D19: =IFERROR(IF(INDEX(BaseDados!$H:$H,MATCH($G$1&"|"&$G19,BaseDados!$A:$A,0))="","",INDEX(BaseDados!$H:$H,MATCH($G$1&"|"&$G19,BaseDados!$A:$A,0))),"") | E19: {=GestorSecretario} -> RONALDO XAVIER DE CARVALHO | F19: =IFERROR(IF(INDEX(BaseDados!$I:$I,MATCH($G$1&"|"&$G19,BaseDados!$A:$A,0))="","",INDEX(BaseDados!$I:$I,MATCH($G$1&"|"&$G19,BaseDados!$A:$A,0))),"") | G19: 15
A20: Checagem de Documentos dos Alunos | B20: Situação | C20: Ultima Atualização | D20: Prazo | E20: Gestor/Secretário | F20: Observação
A21: Fichas de matrícula impressas pelo SIGA e assinadas pelo responsável | B21: =IFERROR(IF(INDEX(BaseDados!$F:$F,MATCH($G$1&"|"&$G21,BaseDados!$A:$A,0))="","",INDEX(BaseDados!$F:$F,MATCH($G$1&"|"&$G21,BaseDados!$A:$A,0))),"") -> Não avaliado | C21: =IFERROR(IF(INDEX(BaseDados!$G:$G,MATCH($G$1&"|"&$G21,BaseDados!$A:$A,0))="","",INDEX(BaseDados!$G:$G,MATCH($G$1&"|"&$G21,BaseDados!$A:$A,0))),"") | D21: =IFERROR(IF(INDEX(BaseDados!$H:$H,MATCH($G$1&"|"&$G21,BaseDados!$A:$A,0))="","",INDEX(BaseDados!$H:$H,MATCH($G$1&"|"&$G21,BaseDados!$A:$A,0))),"") | E21: {=GestorSecretario} -> RONALDO XAVIER DE CARVALHO | F21: =IFERROR(IF(INDEX(BaseDados!$I:$I,MATCH($G$1&"|"&$G21,BaseDados!$A:$A,0))="","",INDEX(BaseDados!$I:$I,MATCH($G$1&"|"&$G21,BaseDados!$A:$A,0))),"") | G21: 16
A22: Histórico Escolar | B22: =IFERROR(IF(INDEX(BaseDados!$F:$F,MATCH($G$1&"|"&$G22,BaseDados!$A:$A,0))="","",INDEX(BaseDados!$F:$F,MATCH($G$1&"|"&$G22,BaseDados!$A:$A,0))),"") -> Não avaliado | C22: =IFERROR(IF(INDEX(BaseDados!$G:$G,MATCH($G$1&"|"&$G22,BaseDados!$A:$A,0))="","",INDEX(BaseDados!$G:$G,MATCH($G$1&"|"&$G22,BaseDados!$A:$A,0))),"") | D22: =IFERROR(IF(INDEX(BaseDados!$H:$H,MATCH($G$1&"|"&$G22,BaseDados!$A:$A,0))="","",INDEX(BaseDados!$H:$H,MATCH($G$1&"|"&$G22,BaseDados!$A:$A,0))),"") | E22: {=GestorSecretario} -> RONALDO XAVIER DE CARVALHO | F22: =IFERROR(IF(INDEX(BaseDados!$I:$I,MATCH($G$1&"|"&$G22,BaseDados!$A:$A,0))="","",INDEX(BaseDados!$I:$I,MATCH($G$1&"|"&$G22,BaseDados!$A:$A,0))),"") | G22: 17
A23: Pasta Individual | B23: =IFERROR(IF(INDEX(BaseDados!$F:$F,MATCH($G$1&"|"&$G23,BaseDados!$A:$A,0))="","",INDEX(BaseDados!$F:$F,MATCH($G$1&"|"&$G23,BaseDados!$A:$A,0))),"") -> Não avaliado | C23: =IFERROR(IF(INDEX(BaseDados!$G:$G,MATCH($G$1&"|"&$G23,BaseDados!$A:$A,0))="","",INDEX(BaseDados!$G:$G,MATCH($G$1&"|"&$G23,BaseDados!$A:$A,0))),"") | D23: =IFERROR(IF(INDEX(BaseDados!$H:$H,MATCH($G$1&"|"&$G23,BaseDados!$A:$A,0))="","",INDEX(BaseDados!$H:$H,MATCH($G$1&"|"&$G23,BaseDados!$A:$A,0))),"") | E23: {=GestorSecretario} -> RONALDO XAVIER DE CARVALHO | F23: =IFERROR(IF(INDEX(BaseDados!$I:$I,MATCH($G$1&"|"&$G23,BaseDados!$A:$A,0))="","",INDEX(BaseDados!$I:$I,MATCH($G$1&"|"&$G23,BaseDados!$A:$A,0))),"") | G23: 18
A24: Registro Síntese | B24: =IFERROR(IF(INDEX(BaseDados!$F:$F,MATCH($G$1&"|"&$G24,BaseDados!$A:$A,0))="","",INDEX(BaseDados!$F:$F,MATCH($G$1&"|"&$G24,BaseDados!$A:$A,0))),"") -> Não avaliado | C24: =IFERROR(IF(INDEX(BaseDados!$G:$G,MATCH($G$1&"|"&$G24,BaseDados!$A:$A,0))="","",INDEX(BaseDados!$G:$G,MATCH($G$1&"|"&$G24,BaseDados!$A:$A,0))),"") | D24: =IFERROR(IF(INDEX(BaseDados!$H:$H,MATCH($G$1&"|"&$G24,BaseDados!$A:$A,0))="","",INDEX(BaseDados!$H:$H,MATCH($G$1&"|"&$G24,BaseDados!$A:$A,0))),"") | E24: {=GestorSecretario} -> RONALDO XAVIER DE CARVALHO | F24: =IFERROR(IF(INDEX(BaseDados!$I:$I,MATCH($G$1&"|"&$G24,BaseDados!$A:$A,0))="","",INDEX(BaseDados!$I:$I,MATCH($G$1&"|"&$G24,BaseDados!$A:$A,0))),"") | G24: 19
A25: Declarações de transferência emitidas pelo SIGA | B25: =IFERROR(IF(INDEX(BaseDados!$F:$F,MATCH($G$1&"|"&$G25,BaseDados!$A:$A,0))="","",INDEX(BaseDados!$F:$F,MATCH($G$1&"|"&$G25,BaseDados!$A:$A,0))),"") -> Não avaliado | C25: =IFERROR(IF(INDEX(BaseDados!$G:$G,MATCH($G$1&"|"&$G25,BaseDados!$A:$A,0))="","",INDEX(BaseDados!$G:$G,MATCH($G$1&"|"&$G25,BaseDados!$A:$A,0))),"") | D25: =IFERROR(IF(INDEX(BaseDados!$H:$H,MATCH($G$1&"|"&$G25,BaseDados!$A:$A,0))="","",INDEX(BaseDados!$H:$H,MATCH($G$1&"|"&$G25,BaseDados!$A:$A,0))),"") | E25: {=GestorSecretario} -> RONALDO XAVIER DE CARVALHO | F25: =IFERROR(IF(INDEX(BaseDados!$I:$I,MATCH($G$1&"|"&$G25,BaseDados!$A:$A,0))="","",INDEX(BaseDados!$I:$I,MATCH($G$1&"|"&$G25,BaseDados!$A:$A,0))),"") | G25: 20
A26: Certificados e declarações emitidos | B26: =IFERROR(IF(INDEX(BaseDados!$F:$F,MATCH($G$1&"|"&$G26,BaseDados!$A:$A,0))="","",INDEX(BaseDados!$F:$F,MATCH($G$1&"|"&$G26,BaseDados!$A:$A,0))),"") -> Não avaliado | C26: =IFERROR(IF(INDEX(BaseDados!$G:$G,MATCH($G$1&"|"&$G26,BaseDados!$A:$A,0))="","",INDEX(BaseDados!$G:$G,MATCH($G$1&"|"&$G26,BaseDados!$A:$A,0))),"") | D26: =IFERROR(IF(INDEX(BaseDados!$H:$H,MATCH($G$1&"|"&$G26,BaseDados!$A:$A,0))="","",INDEX(BaseDados!$H:$H,MATCH($G$1&"|"&$G26,BaseDados!$A:$A,0))),"") | E26: {=GestorSecretario} -> RONALDO XAVIER DE CARVALHO | F26: =IFERROR(IF(INDEX(BaseDados!$I:$I,MATCH($G$1&"|"&$G26,BaseDados!$A:$A,0))="","",INDEX(BaseDados!$I:$I,MATCH($G$1&"|"&$G26,BaseDados!$A:$A,0))),"") | G26: 21
A27: Documentos pessoais do aluno e do responsável | B27: =IFERROR(IF(INDEX(BaseDados!$F:$F,MATCH($G$1&"|"&$G27,BaseDados!$A:$A,0))="","",INDEX(BaseDados!$F:$F,MATCH($G$1&"|"&$G27,BaseDados!$A:$A,0))),"") -> Não avaliado | C27: =IFERROR(IF(INDEX(BaseDados!$G:$G,MATCH($G$1&"|"&$G27,BaseDados!$A:$A,0))="","",INDEX(BaseDados!$G:$G,MATCH($G$1&"|"&$G27,BaseDados!$A:$A,0))),"") | D27: =IFERROR(IF(INDEX(BaseDados!$H:$H,MATCH($G$1&"|"&$G27,BaseDados!$A:$A,0))="","",INDEX(BaseDados!$H:$H,MATCH($G$1&"|"&$G27,BaseDados!$A:$A,0))),"") | E27: {=GestorSecretario} -> RONALDO XAVIER DE CARVALHO | F27: =IFERROR(IF(INDEX(BaseDados!$I:$I,MATCH($G$1&"|"&$G27,BaseDados!$A:$A,0))="","",INDEX(BaseDados!$I:$I,MATCH($G$1&"|"&$G27,BaseDados!$A:$A,0))),"") | G27: 22
A28: Ficha de Cancelamento/Transferência de Matrícula | B28: =IFERROR(IF(INDEX(BaseDados!$F:$F,MATCH($G$1&"|"&$G28,BaseDados!$A:$A,0))="","",INDEX(BaseDados!$F:$F,MATCH($G$1&"|"&$G28,BaseDados!$A:$A,0))),"") -> Não avaliado | C28: =IFERROR(IF(INDEX(BaseDados!$G:$G,MATCH($G$1&"|"&$G28,BaseDados!$A:$A,0))="","",INDEX(BaseDados!$G:$G,MATCH($G$1&"|"&$G28,BaseDados!$A:$A,0))),"") | D28: =IFERROR(IF(INDEX(BaseDados!$H:$H,MATCH($G$1&"|"&$G28,BaseDados!$A:$A,0))="","",INDEX(BaseDados!$H:$H,MATCH($G$1&"|"&$G28,BaseDados!$A:$A,0))),"") | E28: {=GestorSecretario} -> RONALDO XAVIER DE CARVALHO | F28: =IFERROR(IF(INDEX(BaseDados!$I:$I,MATCH($G$1&"|"&$G28,BaseDados!$A:$A,0))="","",INDEX(BaseDados!$I:$I,MATCH($G$1&"|"&$G28,BaseDados!$A:$A,0))),"") | G28: 23
A29: Controle de frequência no SIGA | B29: =IFERROR(IF(INDEX(BaseDados!$F:$F,MATCH($G$1&"|"&$G29,BaseDados!$A:$A,0))="","",INDEX(BaseDados!$F:$F,MATCH($G$1&"|"&$G29,BaseDados!$A:$A,0))),"") -> Não avaliado | C29: =IFERROR(IF(INDEX(BaseDados!$G:$G,MATCH($G$1&"|"&$G29,BaseDados!$A:$A,0))="","",INDEX(BaseDados!$G:$G,MATCH($G$1&"|"&$G29,BaseDados!$A:$A,0))),"") | D29: =IFERROR(IF(INDEX(BaseDados!$H:$H,MATCH($G$1&"|"&$G29,BaseDados!$A:$A,0))="","",INDEX(BaseDados!$H:$H,MATCH($G$1&"|"&$G29,BaseDados!$A:$A,0))),"") | E29: {=GestorSecretario} -> RONALDO XAVIER DE CARVALHO | F29: =IFERROR(IF(INDEX(BaseDados!$I:$I,MATCH($G$1&"|"&$G29,BaseDados!$A:$A,0))="","",INDEX(BaseDados!$I:$I,MATCH($G$1&"|"&$G29,BaseDados!$A:$A,0))),"") | G29: 24
A30: Checagem de Documentos dos Servidores | B30: Situação | C30: Ultima Atualização | D30: Prazo | E30: Gestor/Secretário | F30: Observação
A31: Relação atualizada dos profissionais | B31: =IFERROR(IF(INDEX(BaseDados!$F:$F,MATCH($G$1&"|"&$G31,BaseDados!$A:$A,0))="","",INDEX(BaseDados!$F:$F,MATCH($G$1&"|"&$G31,BaseDados!$A:$A,0))),"") -> Não avaliado | C31: =IFERROR(IF(INDEX(BaseDados!$G:$G,MATCH($G$1&"|"&$G31,BaseDados!$A:$A,0))="","",INDEX(BaseDados!$G:$G,MATCH($G$1&"|"&$G31,BaseDados!$A:$A,0))),"") | D31: =IFERROR(IF(INDEX(BaseDados!$H:$H,MATCH($G$1&"|"&$G31,BaseDados!$A:$A,0))="","",INDEX(BaseDados!$H:$H,MATCH($G$1&"|"&$G31,BaseDados!$A:$A,0))),"") | E31: {=GestorSecretario} -> RONALDO XAVIER DE CARVALHO | F31: =IFERROR(IF(INDEX(BaseDados!$I:$I,MATCH($G$1&"|"&$G31,BaseDados!$A:$A,0))="","",INDEX(BaseDados!$I:$I,MATCH($G$1&"|"&$G31,BaseDados!$A:$A,0))),"") | G31: 25
A32: Portarias de lotação ou designação | B32: =IFERROR(IF(INDEX(BaseDados!$F:$F,MATCH($G$1&"|"&$G32,BaseDados!$A:$A,0))="","",INDEX(BaseDados!$F:$F,MATCH($G$1&"|"&$G32,BaseDados!$A:$A,0))),"") -> Não avaliado | C32: =IFERROR(IF(INDEX(BaseDados!$G:$G,MATCH($G$1&"|"&$G32,BaseDados!$A:$A,0))="","",INDEX(BaseDados!$G:$G,MATCH($G$1&"|"&$G32,BaseDados!$A:$A,0))),"") | D32: =IFERROR(IF(INDEX(BaseDados!$H:$H,MATCH($G$1&"|"&$G32,BaseDados!$A:$A,0))="","",INDEX(BaseDados!$H:$H,MATCH($G$1&"|"&$G32,BaseDados!$A:$A,0))),"") | E32: {=GestorSecretario} -> RONALDO XAVIER DE CARVALHO | F32: =IFERROR(IF(INDEX(BaseDados!$I:$I,MATCH($G$1&"|"&$G32,BaseDados!$A:$A,0))="","",INDEX(BaseDados!$I:$I,MATCH($G$1&"|"&$G32,BaseDados!$A:$A,0))),"") | G32: 26
A33: Comprovação da habilitação dos docentes | B33: =IFERROR(IF(INDEX(BaseDados!$F:$F,MATCH($G$1&"|"&$G33,BaseDados!$A:$A,0))="","",INDEX(BaseDados!$F:$F,MATCH($G$1&"|"&$G33,BaseDados!$A:$A,0))),"") -> Não avaliado | C33: =IFERROR(IF(INDEX(BaseDados!$G:$G,MATCH($G$1&"|"&$G33,BaseDados!$A:$A,0))="","",INDEX(BaseDados!$G:$G,MATCH($G$1&"|"&$G33,BaseDados!$A:$A,0))),"") | D33: =IFERROR(IF(INDEX(BaseDados!$H:$H,MATCH($G$1&"|"&$G33,BaseDados!$A:$A,0))="","",INDEX(BaseDados!$H:$H,MATCH($G$1&"|"&$G33,BaseDados!$A:$A,0))),"") | E33: {=GestorSecretario} -> RONALDO XAVIER DE CARVALHO | F33: =IFERROR(IF(INDEX(BaseDados!$I:$I,MATCH($G$1&"|"&$G33,BaseDados!$A:$A,0))="","",INDEX(BaseDados!$I:$I,MATCH($G$1&"|"&$G33,BaseDados!$A:$A,0))),"") | G33: 27
A34: Controle de frequência dos servidores | B34: =IFERROR(IF(INDEX(BaseDados!$F:$F,MATCH($G$1&"|"&$G34,BaseDados!$A:$A,0))="","",INDEX(BaseDados!$F:$F,MATCH($G$1&"|"&$G34,BaseDados!$A:$A,0))),"") -> Não avaliado | C34: =IFERROR(IF(INDEX(BaseDados!$G:$G,MATCH($G$1&"|"&$G34,BaseDados!$A:$A,0))="","",INDEX(BaseDados!$G:$G,MATCH($G$1&"|"&$G34,BaseDados!$A:$A,0))),"") | D34: =IFERROR(IF(INDEX(BaseDados!$H:$H,MATCH($G$1&"|"&$G34,BaseDados!$A:$A,0))="","",INDEX(BaseDados!$H:$H,MATCH($G$1&"|"&$G34,BaseDados!$A:$A,0))),"") | E34: {=GestorSecretario} -> RONALDO XAVIER DE CARVALHO | F34: =IFERROR(IF(INDEX(BaseDados!$I:$I,MATCH($G$1&"|"&$G34,BaseDados!$A:$A,0))="","",INDEX(BaseDados!$I:$I,MATCH($G$1&"|"&$G34,BaseDados!$A:$A,0))),"") | G34: 28
A35: Afastamentos dos servidores — licenças e documentos médicos | B35: =IFERROR(IF(INDEX(BaseDados!$F:$F,MATCH($G$1&"|"&$G35,BaseDados!$A:$A,0))="","",INDEX(BaseDados!$F:$F,MATCH($G$1&"|"&$G35,BaseDados!$A:$A,0))),"") -> Não avaliado | C35: =IFERROR(IF(INDEX(BaseDados!$G:$G,MATCH($G$1&"|"&$G35,BaseDados!$A:$A,0))="","",INDEX(BaseDados!$G:$G,MATCH($G$1&"|"&$G35,BaseDados!$A:$A,0))),"") | D35: =IFERROR(IF(INDEX(BaseDados!$H:$H,MATCH($G$1&"|"&$G35,BaseDados!$A:$A,0))="","",INDEX(BaseDados!$H:$H,MATCH($G$1&"|"&$G35,BaseDados!$A:$A,0))),"") | E35: {=GestorSecretario} -> RONALDO XAVIER DE CARVALHO | F35: =IFERROR(IF(INDEX(BaseDados!$I:$I,MATCH($G$1&"|"&$G35,BaseDados!$A:$A,0))="","",INDEX(BaseDados!$I:$I,MATCH($G$1&"|"&$G35,BaseDados!$A:$A,0))),"") | G35: 29
A36: Checagem de Documentos dos Administrativos | B36: Situação | C36: Ultima Atualização | D36: Prazo | E36: Gestor/Secretário | F36: Observação
A37: Censo Escolar | B37: =IFERROR(IF(INDEX(BaseDados!$F:$F,MATCH($G$1&"|"&$G37,BaseDados!$A:$A,0))="","",INDEX(BaseDados!$F:$F,MATCH($G$1&"|"&$G37,BaseDados!$A:$A,0))),"") -> Não avaliado | C37: =IFERROR(IF(INDEX(BaseDados!$G:$G,MATCH($G$1&"|"&$G37,BaseDados!$A:$A,0))="","",INDEX(BaseDados!$G:$G,MATCH($G$1&"|"&$G37,BaseDados!$A:$A,0))),"") | D37: =IFERROR(IF(INDEX(BaseDados!$H:$H,MATCH($G$1&"|"&$G37,BaseDados!$A:$A,0))="","",INDEX(BaseDados!$H:$H,MATCH($G$1&"|"&$G37,BaseDados!$A:$A,0))),"") | E37: {=GestorSecretario} -> RONALDO XAVIER DE CARVALHO | F37: =IFERROR(IF(INDEX(BaseDados!$I:$I,MATCH($G$1&"|"&$G37,BaseDados!$A:$A,0))="","",INDEX(BaseDados!$I:$I,MATCH($G$1&"|"&$G37,BaseDados!$A:$A,0))),"") | G37: 30
A38: Relação nominal dos estudantes | B38: =IFERROR(IF(INDEX(BaseDados!$F:$F,MATCH($G$1&"|"&$G38,BaseDados!$A:$A,0))="","",INDEX(BaseDados!$F:$F,MATCH($G$1&"|"&$G38,BaseDados!$A:$A,0))),"") -> Não avaliado | C38: =IFERROR(IF(INDEX(BaseDados!$G:$G,MATCH($G$1&"|"&$G38,BaseDados!$A:$A,0))="","",INDEX(BaseDados!$G:$G,MATCH($G$1&"|"&$G38,BaseDados!$A:$A,0))),"") | D38: =IFERROR(IF(INDEX(BaseDados!$H:$H,MATCH($G$1&"|"&$G38,BaseDados!$A:$A,0))="","",INDEX(BaseDados!$H:$H,MATCH($G$1&"|"&$G38,BaseDados!$A:$A,0))),"") | E38: {=GestorSecretario} -> RONALDO XAVIER DE CARVALHO | F38: =IFERROR(IF(INDEX(BaseDados!$I:$I,MATCH($G$1&"|"&$G38,BaseDados!$A:$A,0))="","",INDEX(BaseDados!$I:$I,MATCH($G$1&"|"&$G38,BaseDados!$A:$A,0))),"") | G38: 31
A39: Relatórios estatísticos | B39: =IFERROR(IF(INDEX(BaseDados!$F:$F,MATCH($G$1&"|"&$G39,BaseDados!$A:$A,0))="","",INDEX(BaseDados!$F:$F,MATCH($G$1&"|"&$G39,BaseDados!$A:$A,0))),"") -> Não avaliado | C39: =IFERROR(IF(INDEX(BaseDados!$G:$G,MATCH($G$1&"|"&$G39,BaseDados!$A:$A,0))="","",INDEX(BaseDados!$G:$G,MATCH($G$1&"|"&$G39,BaseDados!$A:$A,0))),"") | D39: =IFERROR(IF(INDEX(BaseDados!$H:$H,MATCH($G$1&"|"&$G39,BaseDados!$A:$A,0))="","",INDEX(BaseDados!$H:$H,MATCH($G$1&"|"&$G39,BaseDados!$A:$A,0))),"") | E39: {=GestorSecretario} -> RONALDO XAVIER DE CARVALHO | F39: =IFERROR(IF(INDEX(BaseDados!$I:$I,MATCH($G$1&"|"&$G39,BaseDados!$A:$A,0))="","",INDEX(BaseDados!$I:$I,MATCH($G$1&"|"&$G39,BaseDados!$A:$A,0))),"") | G39: 32
A40: Correspondências oficiais | B40: =IFERROR(IF(INDEX(BaseDados!$F:$F,MATCH($G$1&"|"&$G40,BaseDados!$A:$A,0))="","",INDEX(BaseDados!$F:$F,MATCH($G$1&"|"&$G40,BaseDados!$A:$A,0))),"") -> Não avaliado | C40: =IFERROR(IF(INDEX(BaseDados!$G:$G,MATCH($G$1&"|"&$G40,BaseDados!$A:$A,0))="","",INDEX(BaseDados!$G:$G,MATCH($G$1&"|"&$G40,BaseDados!$A:$A,0))),"") | D40: =IFERROR(IF(INDEX(BaseDados!$H:$H,MATCH($G$1&"|"&$G40,BaseDados!$A:$A,0))="","",INDEX(BaseDados!$H:$H,MATCH($G$1&"|"&$G40,BaseDados!$A:$A,0))),"") | E40: {=GestorSecretario} -> RONALDO XAVIER DE CARVALHO | F40: =IFERROR(IF(INDEX(BaseDados!$I:$I,MATCH($G$1&"|"&$G40,BaseDados!$A:$A,0))="","",INDEX(BaseDados!$I:$I,MATCH($G$1&"|"&$G40,BaseDados!$A:$A,0))),"") | G40: 33
...
